[2024-09-25 19:19:31,812] INFO _log() L97   [31m[1mWARNING: This is a development server. Do not use it in a production deployment. Use a production WSGI server instead.[0m
 * Running on all addresses (0.0.0.0)
 * Running on http://127.0.0.1:5000
 * Running on http://172.24.235.173:5000 - call_trace=/home/slsn/repos/mvp3_1/.venv/lib/python3.10/site-packages/werkzeug/_internal.py L97  
[2024-09-25 19:19:31,812] INFO _log() L97   [33mPress CTRL+C to quit[0m - call_trace=/home/slsn/repos/mvp3_1/.venv/lib/python3.10/site-packages/werkzeug/_internal.py L97  
[2024-09-25 19:19:39,536] WARNING get_imoveis() L59   N√£o h√° imoveis cadastrados na base :/ - call_trace=/home/slsn/repos/mvp3_1/api/app.py L59  
[2024-09-25 19:19:39,536] INFO _log() L97   127.0.0.1 - - [25/Sep/2024 19:19:39] "[33mGET /imoveis HTTP/1.1[0m" 404 - - call_trace=/home/slsn/repos/mvp3_1/.venv/lib/python3.10/site-packages/werkzeug/_internal.py L97  
[2024-09-25 20:03:34,991] WARNING get_imoveis() L59   N√£o h√° imoveis cadastrados na base :/ - call_trace=/home/slsn/repos/mvp3_1/api/app.py L59  
[2024-09-25 20:03:34,993] INFO _log() L97   127.0.0.1 - - [25/Sep/2024 20:03:34] "[33mGET /imoveis HTTP/1.1[0m" 404 - - call_trace=/home/slsn/repos/mvp3_1/.venv/lib/python3.10/site-packages/werkzeug/_internal.py L97  
[2024-09-25 20:03:36,208] WARNING get_imoveis() L59   N√£o h√° imoveis cadastrados na base :/ - call_trace=/home/slsn/repos/mvp3_1/api/app.py L59  
[2024-09-25 20:03:36,209] INFO _log() L97   127.0.0.1 - - [25/Sep/2024 20:03:36] "[33mGET /imoveis HTTP/1.1[0m" 404 - - call_trace=/home/slsn/repos/mvp3_1/.venv/lib/python3.10/site-packages/werkzeug/_internal.py L97  
[2024-09-25 20:03:58,661] WARNING get_imovel() L167  Erro ao buscar imovel do propriet√°rio 'aaa', Imovel do propriet√°rio aaa n√£o encontrado na base :/ - call_trace=/home/slsn/repos/mvp3_1/api/app.py L167 
[2024-09-25 20:03:58,662] INFO _log() L97   127.0.0.1 - - [25/Sep/2024 20:03:58] "[33mGET /imovel?owner_name=aaa HTTP/1.1[0m" 404 - - call_trace=/home/slsn/repos/mvp3_1/.venv/lib/python3.10/site-packages/werkzeug/_internal.py L97  
[2024-09-25 20:04:53,403] WARNING get_imovel() L167  Erro ao buscar imovel do propriet√°rio 'aaa', Imovel do propriet√°rio aaa n√£o encontrado na base :/ - call_trace=/home/slsn/repos/mvp3_1/api/app.py L167 
[2024-09-25 20:04:53,403] INFO _log() L97   127.0.0.1 - - [25/Sep/2024 20:04:53] "[33mGET /imovel?owner_name=aaa HTTP/1.1[0m" 404 - - call_trace=/home/slsn/repos/mvp3_1/.venv/lib/python3.10/site-packages/werkzeug/_internal.py L97  
[2024-09-25 20:06:41,987] WARNING get_imoveis() L59   N√£o h√° imoveis cadastrados na base :/ - call_trace=/home/slsn/repos/mvp3_1/api/app.py L59  
[2024-09-25 20:06:41,987] INFO _log() L97   127.0.0.1 - - [25/Sep/2024 20:06:41] "[33mGET /imoveis HTTP/1.1[0m" 404 - - call_trace=/home/slsn/repos/mvp3_1/.venv/lib/python3.10/site-packages/werkzeug/_internal.py L97  
[2024-09-25 20:07:12,954] ERROR log_exception() L838  Exception on /imovel [POST] - call_trace=/home/slsn/repos/mvp3_1/.venv/lib/python3.10/site-packages/flask/app.py L838 
Traceback (most recent call last):
  File "/home/slsn/repos/mvp3_1/.venv/lib/python3.10/site-packages/flask/app.py", line 1473, in wsgi_app
    response = self.full_dispatch_request()
  File "/home/slsn/repos/mvp3_1/.venv/lib/python3.10/site-packages/flask/app.py", line 882, in full_dispatch_request
    rv = self.handle_user_exception(e)
  File "/home/slsn/repos/mvp3_1/.venv/lib/python3.10/site-packages/flask_cors/extension.py", line 194, in wrapped_function
    return cors_after_request(app.make_response(f(*args, **kwargs)))
  File "/home/slsn/repos/mvp3_1/.venv/lib/python3.10/site-packages/flask/app.py", line 880, in full_dispatch_request
    rv = self.dispatch_request()
  File "/home/slsn/repos/mvp3_1/.venv/lib/python3.10/site-packages/flask/app.py", line 865, in dispatch_request
    return self.ensure_sync(self.view_functions[rule.endpoint])(**view_args)  # type: ignore[no-any-return]
  File "/home/slsn/repos/mvp3_1/.venv/lib/python3.10/site-packages/flask_openapi3/scaffold.py", line 117, in view_func
    response = func(**func_kwargs)
  File "/home/slsn/repos/mvp3_1/api/app.py", line 91, in predict
    modelo = Model.carrega_modelo(ml_path)
TypeError: Model.carrega_modelo() missing 1 required positional argument: 'path'
[2024-09-25 20:07:12,956] INFO _log() L97   127.0.0.1 - - [25/Sep/2024 20:07:12] "[35m[1mPOST /imovel HTTP/1.1[0m" 500 - - call_trace=/home/slsn/repos/mvp3_1/.venv/lib/python3.10/site-packages/werkzeug/_internal.py L97  
[2024-09-25 20:08:12,144] INFO _log() L97   [31m[1mWARNING: This is a development server. Do not use it in a production deployment. Use a production WSGI server instead.[0m
 * Running on all addresses (0.0.0.0)
 * Running on http://127.0.0.1:5000
 * Running on http://172.24.235.173:5000 - call_trace=/home/slsn/repos/mvp3_1/.venv/lib/python3.10/site-packages/werkzeug/_internal.py L97  
[2024-09-25 20:08:12,144] INFO _log() L97   [33mPress CTRL+C to quit[0m - call_trace=/home/slsn/repos/mvp3_1/.venv/lib/python3.10/site-packages/werkzeug/_internal.py L97  
[2024-09-25 20:08:16,868] INFO _log() L97   127.0.0.1 - - [25/Sep/2024 20:08:16] "GET /openapi/swagger HTTP/1.1" 200 - - call_trace=/home/slsn/repos/mvp3_1/.venv/lib/python3.10/site-packages/werkzeug/_internal.py L97  
[2024-09-25 20:08:16,892] INFO _log() L97   127.0.0.1 - - [25/Sep/2024 20:08:16] "[36mGET /openapi/static/css/swagger-ui.css HTTP/1.1[0m" 304 - - call_trace=/home/slsn/repos/mvp3_1/.venv/lib/python3.10/site-packages/werkzeug/_internal.py L97  
[2024-09-25 20:08:16,893] INFO _log() L97   127.0.0.1 - - [25/Sep/2024 20:08:16] "[36mGET /openapi/static/js/swagger-ui-bundle.js HTTP/1.1[0m" 304 - - call_trace=/home/slsn/repos/mvp3_1/.venv/lib/python3.10/site-packages/werkzeug/_internal.py L97  
[2024-09-25 20:08:16,895] INFO _log() L97   127.0.0.1 - - [25/Sep/2024 20:08:16] "[36mGET /openapi/static/js/swagger-ui-standalone-preset.js HTTP/1.1[0m" 304 - - call_trace=/home/slsn/repos/mvp3_1/.venv/lib/python3.10/site-packages/werkzeug/_internal.py L97  
[2024-09-25 20:08:17,109] INFO _log() L97   127.0.0.1 - - [25/Sep/2024 20:08:17] "GET /openapi/openapi.json HTTP/1.1" 200 - - call_trace=/home/slsn/repos/mvp3_1/.venv/lib/python3.10/site-packages/werkzeug/_internal.py L97  
[2024-09-25 20:08:17,153] INFO _log() L97   127.0.0.1 - - [25/Sep/2024 20:08:17] "[36mGET /openapi/static/images/swagger.svg HTTP/1.1[0m" 304 - - call_trace=/home/slsn/repos/mvp3_1/.venv/lib/python3.10/site-packages/werkzeug/_internal.py L97  
[2024-09-25 20:08:39,809] ERROR log_exception() L838  Exception on /imovel [POST] - call_trace=/home/slsn/repos/mvp3_1/.venv/lib/python3.10/site-packages/flask/app.py L838 
Traceback (most recent call last):
  File "/home/slsn/repos/mvp3_1/.venv/lib/python3.10/site-packages/flask/app.py", line 1473, in wsgi_app
    response = self.full_dispatch_request()
  File "/home/slsn/repos/mvp3_1/.venv/lib/python3.10/site-packages/flask/app.py", line 882, in full_dispatch_request
    rv = self.handle_user_exception(e)
  File "/home/slsn/repos/mvp3_1/.venv/lib/python3.10/site-packages/flask_cors/extension.py", line 194, in wrapped_function
    return cors_after_request(app.make_response(f(*args, **kwargs)))
  File "/home/slsn/repos/mvp3_1/.venv/lib/python3.10/site-packages/flask/app.py", line 880, in full_dispatch_request
    rv = self.dispatch_request()
  File "/home/slsn/repos/mvp3_1/.venv/lib/python3.10/site-packages/flask/app.py", line 865, in dispatch_request
    return self.ensure_sync(self.view_functions[rule.endpoint])(**view_args)  # type: ignore[no-any-return]
  File "/home/slsn/repos/mvp3_1/.venv/lib/python3.10/site-packages/flask_openapi3/scaffold.py", line 117, in view_func
    response = func(**func_kwargs)
  File "/home/slsn/repos/mvp3_1/api/app.py", line 91, in predict
    modelo = Model.carrega_modelo(ml_path)
TypeError: Model.carrega_modelo() missing 1 required positional argument: 'path'
[2024-09-25 20:08:39,811] INFO _log() L97   127.0.0.1 - - [25/Sep/2024 20:08:39] "[35m[1mPOST /imovel HTTP/1.1[0m" 500 - - call_trace=/home/slsn/repos/mvp3_1/.venv/lib/python3.10/site-packages/werkzeug/_internal.py L97  
[2024-09-25 20:10:32,717] INFO _log() L97   [31m[1mWARNING: This is a development server. Do not use it in a production deployment. Use a production WSGI server instead.[0m
 * Running on all addresses (0.0.0.0)
 * Running on http://127.0.0.1:5000
 * Running on http://172.24.235.173:5000 - call_trace=/home/slsn/repos/mvp3_1/.venv/lib/python3.10/site-packages/werkzeug/_internal.py L97  
[2024-09-25 20:10:32,717] INFO _log() L97   [33mPress CTRL+C to quit[0m - call_trace=/home/slsn/repos/mvp3_1/.venv/lib/python3.10/site-packages/werkzeug/_internal.py L97  
[2024-09-25 20:10:40,465] INFO _log() L97   127.0.0.1 - - [25/Sep/2024 20:10:40] "POST /imovel HTTP/1.1" 200 - - call_trace=/home/slsn/repos/mvp3_1/.venv/lib/python3.10/site-packages/werkzeug/_internal.py L97  
[2024-09-25 20:10:49,334] INFO _log() L97   127.0.0.1 - - [25/Sep/2024 20:10:49] "POST /imovel HTTP/1.1" 200 - - call_trace=/home/slsn/repos/mvp3_1/.venv/lib/python3.10/site-packages/werkzeug/_internal.py L97  
[2024-09-25 20:11:01,457] WARNING get_imovel() L168  Erro ao buscar imovel do propriet√°rio 'aaa', Imovel do propriet√°rio aaa n√£o encontrado na base :/ - call_trace=/home/slsn/repos/mvp3_1/api/app.py L168 
[2024-09-25 20:11:01,458] INFO _log() L97   127.0.0.1 - - [25/Sep/2024 20:11:01] "[33mGET /imovel?owner_name=aaa HTTP/1.1[0m" 404 - - call_trace=/home/slsn/repos/mvp3_1/.venv/lib/python3.10/site-packages/werkzeug/_internal.py L97  
[2024-09-25 20:11:11,689] INFO _log() L97   127.0.0.1 - - [25/Sep/2024 20:11:11] "GET /imoveis HTTP/1.1" 200 - - call_trace=/home/slsn/repos/mvp3_1/.venv/lib/python3.10/site-packages/werkzeug/_internal.py L97  
